Traceback (most recent call last):
  File "/home/mfvargas/miniconda3/envs/gf0657-2024-ii/lib/python3.12/site-packages/jupyter_cache/executors/utils.py", line 58, in single_nb_execution
    executenb(
  File "/home/mfvargas/miniconda3/envs/gf0657-2024-ii/lib/python3.12/site-packages/nbclient/client.py", line 1314, in execute
    return NotebookClient(nb=nb, resources=resources, km=km, **kwargs).execute()
           ^^^^^^^^^^^^^^^^^^^^^^^^^^^^^^^^^^^^^^^^^^^^^^^^^^^^^^^^^^^^^^^^^^^^^
  File "/home/mfvargas/miniconda3/envs/gf0657-2024-ii/lib/python3.12/site-packages/jupyter_core/utils/__init__.py", line 165, in wrapped
    return loop.run_until_complete(inner)
           ^^^^^^^^^^^^^^^^^^^^^^^^^^^^^^
  File "/home/mfvargas/miniconda3/envs/gf0657-2024-ii/lib/python3.12/asyncio/base_events.py", line 687, in run_until_complete
    return future.result()
           ^^^^^^^^^^^^^^^
  File "/home/mfvargas/miniconda3/envs/gf0657-2024-ii/lib/python3.12/site-packages/nbclient/client.py", line 709, in async_execute
    await self.async_execute_cell(
  File "/home/mfvargas/miniconda3/envs/gf0657-2024-ii/lib/python3.12/site-packages/nbclient/client.py", line 1062, in async_execute_cell
    await self._check_raise_for_error(cell, cell_index, exec_reply)
  File "/home/mfvargas/miniconda3/envs/gf0657-2024-ii/lib/python3.12/site-packages/nbclient/client.py", line 918, in _check_raise_for_error
    raise CellExecutionError.from_cell_and_msg(cell, exec_reply_content)
nbclient.exceptions.CellExecutionError: An error occurred while executing the following cell:
------------------
# Dataframe generado a partir de un diccionario

diccionario_paises = {
  "pais": ["PA", "CR", "NI"],
  "poblacion": [4246439, 5047561, 6545502]
}

df_paises = pd.DataFrame(datos)

df_paises
------------------


[0;31m---------------------------------------------------------------------------[0m
[0;31mNameError[0m                                 Traceback (most recent call last)
Cell [0;32mIn[7], line 8[0m
[1;32m      1[0m [38;5;66;03m# Dataframe generado a partir de un diccionario[39;00m
[1;32m      3[0m diccionario_paises [38;5;241m=[39m {
[1;32m      4[0m   [38;5;124m"[39m[38;5;124mpais[39m[38;5;124m"[39m: [[38;5;124m"[39m[38;5;124mPA[39m[38;5;124m"[39m, [38;5;124m"[39m[38;5;124mCR[39m[38;5;124m"[39m, [38;5;124m"[39m[38;5;124mNI[39m[38;5;124m"[39m],
[1;32m      5[0m   [38;5;124m"[39m[38;5;124mpoblacion[39m[38;5;124m"[39m: [[38;5;241m4246439[39m, [38;5;241m5047561[39m, [38;5;241m6545502[39m]
[1;32m      6[0m }
[0;32m----> 8[0m df_paises [38;5;241m=[39m pd[38;5;241m.[39mDataFrame([43mdatos[49m)
[1;32m     10[0m df_paises

[0;31mNameError[0m: name 'datos' is not defined

